Workbook

Sheet Overview
B2: Campus Ready Foundation
B3: 2026 Cohort — Program Cost Analysis
B4: Prepared for Board Review | May 2026 | 41 eligible students
B7: 41 | C7: =C19 -> 58970 | D7: ="$"&TEXT(E21,"#,##0") -> $47,426 | E7: ='Travel Detail'!R50 -> 12576
B8: Eligible Students | C8: Total Cost to Serve | D8: Total Recommended Budget | E8: Travel Budget (rec'd)
B9: 2026 grant cycle | C9: all program components | D9: incl. contingency & CollegeBoxes | E9: travel + 15% contingency
B12: Program Cost Summary
B13: Cost Category | C13: Total Cost | D13: Partner Credits | E13: CRF Cash Outlay
B14: Travel (inc. airport Lyft, companion ground) | C14: ='Program Cost Pro Forma'!D48 -> 15545 | D14: ='Program Cost Pro Forma'!K48 -> 4609 | E14: ='Travel Detail'!R48 -> 10936
B15: Products ($750/student) | C15: ='Program Cost Pro Forma'!E48 -> 30750 | D15: 0 | E15: ='Program Cost Pro Forma'!E48 -> 30750
B16: DoorDash meals ($100/student) | C16: ='Program Cost Pro Forma'!F48 -> 4100 | D16: ='Program Cost Pro Forma'!L48 -> 4100 | E16: =C16-D16 -> 0
B17: Gift card ($100/student) | C17: ='Program Cost Pro Forma'!G48 -> 4100 | D17: 0 | E17: ='Program Cost Pro Forma'!G48 -> 4100
B18: CollegeBoxes shipping (PENDING APPROVAL) | C18: ='Program Cost Pro Forma'!I48 -> 4475 | D18: 0
B19: SUBTOTAL | C19: =SUM(C14:C18) -> 58970 | D19: =SUM(D14:D18) -> 8709 | E19: =SUM(E14:E17) -> 45786
B20: 15% Contingency on Travel Cash Outlay | E20: ='Travel Detail'!R49 -> 1640
B21: TOTAL RECOMMENDED PROGRAM BUDGET | E21: =SUM(E19:E20) -> 47426
B22: ⚠ CollegeBoxes shipping ($4,175 total) is PENDING BOARD APPROVAL — included above for planning only. Also contingent on school advance-shipping policy: CRF pays CollegeBoxes ONLY for schools that don't allow direct Amazon shipping. BU confirmed (no advance shipping). All other schools TBD — research required.

Sheet Travel Detail
B2: Campus Ready Foundation — 2026 Cohort Travel Detail
B3: Blue = editable. Flight/short-haul: H=fare, I=airport Lyft (home→dep + arr→campus). Road trip: H=gas card (fuel+15% contingency), J=companion return flight. Lyft-direct: H=Lyft XL to campus. Lyft credit applies to student's Lyft component only (col I for flight, col H for Lyft-direct). Hotel: companion travelers only — solo students go direct to dorm. Lyft threshold: ≤200 miles. 200–250 miles: flight preferred.
K5: <- Edit these cells
B6: Student Name | C6: Home | D6: College | E6: College City/State | F6: Miles | G6: Driving? (Y/N) | H6: Departure Airport | I6: Destination Airport | J6: Transport Mode | K6: Primary Transport | L6: Airport Lyft | M6: Companion Transport | N6: Companion Ground | O6: Hotel | P6: Total Travel Cost | Q6: Lyft Credit | R6: CRF Cash Outlay | T6: Ships to Dorm?
B7: Alice Lilliane Baxter | C7: Saint Helena, CA | D7: UC Santa Cruz | E7: Santa Cruz, CA | F7: 142 | H7: N/A | I7: N/A | J7: Lyft | K7: 234 | L7: 0 | M7: 0 | N7: 0 | O7: 0 | P7: =K7+L7+M7+N7+O7 -> 234 | Q7: =IF(K7>0,MIN(K7,150),0) -> 150 | R7: =MAX(0,P7-Q7) -> 84 | T7: TBD
B8: Amara S. Boerner | C8: Santa Rosa, CA | D8: CSU San Marcos | E8: San Marcos, CA | F8: 531 | H8: SFO | I8: SAN | J8: Flight | K8: 135 | L8: 173 | M8: 270 | N8: 50 | O8: 200 | P8: =K8+L8+M8+N8+O8 -> 828 | Q8: =IF(L8>0,MIN(L8,150),0) -> 150 | R8: =MAX(0,P8-Q8) -> 678 | T8: TBD
B9: Anastasia Guerrier | C9: Miami, FL | D9: College of Saint Benedict | E9: Saint Joseph, MN | F9: 1861 | G9: Y | H9: N/A | I9: N/A | J9: Road trip (self-drive) | K9: 268 | L9: 0 | M9: 200 | N9: 0 | O9: 400 | P9: =K9+L9+M9+N9+O9 -> 868 | Q9: =IF(L9>0,MIN(L9,150),0) -> 0 | R9: =MAX(0,P9-Q9) -> 868 | T9: N/A
B10: Andrea Elia Suarez | C10: Napa, CA | D10: UC Merced | E10: Merced, CA | F10: 156 | H10: N/A | I10: N/A | J10: Lyft | K10: 257 | L10: 0 | M10: 0 | N10: 0 | O10: 0 | P10: =K10+L10+M10+N10+O10 -> 257 | Q10: =IF(K10>0,MIN(K10,150),0) -> 150 | R10: =MAX(0,P10-Q10) -> 107 | T10: TBD
B11: Angelina Montero | C11: Rohnert Park, CA | D11: UC Davis | E11: Davis, CA | F11: 78 | H11: N/A | I11: N/A | J11: Lyft | K11: 129 | L11: 0 | M11: 0 | N11: 0 | O11: 0 | P11: =K11+L11+M11+N11+O11 -> 129 | Q11: =IF(K11>0,MIN(K11,150),0) -> 129 | R11: =MAX(0,P11-Q11) -> 0 | T11: TBD
B12: Antonio Rivera | C12: Santa Rosa, CA | D12: UC Santa Cruz | E12: Santa Cruz, CA | F12: 132 | H12: N/A | I12: N/A | J12: Lyft | K12: 218 | L12: 0 | M12: 0 | N12: 0 | O12: 0 | P12: =K12+L12+M12+N12+O12 -> 218 | Q12: =IF(K12>0,MIN(K12,150),0) -> 150 | R12: =MAX(0,P12-Q12) -> 68 | T12: TBD
B13: Arianna Deibert | C13: Napa, CA | D13: San Diego State University | E13: San Diego, CA | F13: 524 | H13: SFO | I13: SAN | J13: Flight | K13: 135 | L13: 94 | M13: 0 | N13: 0 | O13: 0 | P13: =K13+L13+M13+N13+O13 -> 229 | Q13: =IF(L13>0,MIN(L13,150),0) -> 94 | R13: =MAX(0,P13-Q13) -> 135 | T13: TBD
B14: Cristian Gustavo Fonseca Nunez | C14: Santa Rosa, CA | D14: UC Davis | E14: Davis, CA | F14: 88 | H14: N/A | I14: N/A | J14: Lyft | K14: 145 | L14: 0 | M14: 0 | N14: 0 | O14: 0 | P14: =K14+L14+M14+N14+O14 -> 145 | Q14: =IF(K14>0,MIN(K14,150),0) -> 145 | R14: =MAX(0,P14-Q14) -> 0 | T14: TBD
B15: Daniel Orozco Reyna | C15: Santa Rosa, CA | D15: CSU Monterey Bay | E15: Marina, CA | F15: 166 | H15: N/A | I15: N/A | J15: Lyft | K15: 274 | L15: 0 | M15: 274 | N15: 0 | O15: 0 | P15: =K15+L15+M15+N15+O15 -> 548 | Q15: =IF(K15>0,MIN(K15,150),0) -> 150 | R15: =MAX(0,P15-Q15) -> 398 | T15: TBD
B16: Daniel Sanchez | C16: Vallejo, CA | D16: CSU Chico | E16: Chico, CA | F16: 133 | H16: N/A | I16: N/A | J16: Lyft | K16: 219 | L16: 0 | M16: 219 | N16: 0 | O16: 0 | P16: =K16+L16+M16+N16+O16 -> 438 | Q16: =IF(K16>0,MIN(K16,150),0) -> 150 | R16: =MAX(0,P16-Q16) -> 288 | T16: TBD
B17: Daysee Jossabeth Queme Mazariegos | C17: American Canyon, CA | D17: Napa Valley College | E17: Napa, CA | F17: 12 | H17: N/A | I17: N/A | J17: Lyft | K17: 25 | L17: 0 | M17: 0 | N17: 0 | O17: 0 | P17: =K17+L17+M17+N17+O17 -> 25 | Q17: =IF(K17>0,MIN(K17,150),0) -> 25 | R17: =MAX(0,P17-Q17) -> 0 | T17: TBD
B18: Diana Sofia Romero Sam | C18: Angwin, CA | D18: UC Santa Cruz | E18: Santa Cruz, CA | F18: 143 | H18: N/A | I18: N/A | J18: Lyft | K18: 236 | L18: 0 | M18: 236 | N18: 0 | O18: 0 | P18: =K18+L18+M18+N18+O18 -> 472 | Q18: =IF(K18>0,MIN(K18,150),0) -> 150 | R18: =MAX(0,P18-Q18) -> 322 | T18: TBD
B19: Diego Perez Herrera | C19: Calistoga, CA | D19: San Jose State Univ | E19: San Jose, CA | F19: 115 | H19: N/A | I19: N/A | J19: Lyft | K19: 190 | L19: 0 | M19: 0 | N19: 0 | O19: 0 | P19: =K19+L19+M19+N19+O19 -> 190 | Q19: =IF(K19>0,MIN(K19,150),0) -> 150 | R19: =MAX(0,P19-Q19) -> 40 | T19: TBD
B20: Elizabeth Carmichael | C20: Angwin, CA | D20: Denison University | E20: Granville, OH | F20: 2478 | H20: SFO | I20: CMH | J20: Cross-country flight | K20: 200 | L20: 175 | M20: 400 | N20: 50 | O20: 400 | P20: =K20+L20+M20+N20+O20 -> 1225 | Q20: =IF(L20>0,MIN(L20,150),0) -> 150 | R20: =MAX(0,P20-Q20) -> 1075 | T20: TBD
B21: Fernanda Guadalupe Contreras Alcaraz | C21: Santa Rosa, CA | D21: UC Davis | E21: Davis, CA | F21: 87 | H21: N/A | I21: N/A | J21: Lyft | K21: 144 | L21: 0 | M21: 0 | N21: 0 | O21: 0 | P21: =K21+L21+M21+N21+O21 -> 144 | Q21: =IF(K21>0,MIN(K21,150),0) -> 144 | R21: =MAX(0,P21-Q21) -> 0 | T21: TBD
B22: Gabrielle Pina | C22: Brockton, MA | D22: Whittier College | E22: Whittier, CA | F22: 2989 | H22: BOS | I22: LAX | J22: Cross-country flight | K22: 220 | L22: 62 | M22: 0 | N22: 0 | O22: 0 | P22: =K22+L22+M22+N22+O22 -> 282 | Q22: =IF(L22>0,MIN(L22,150),0) -> 62 | R22: =MAX(0,P22-Q22) -> 220 | T22: TBD
B23: Henry Ray | C23: St. Helena, CA | D23: Oregon State Univ - Cascades | E23: Bend, OR | F23: 483 | H23: SFO | I23: RDM | J23: Short-haul flight | K23: 135 | L23: 162 | M23: 270 | N23: 50 | O23: 200 | P23: =K23+L23+M23+N23+O23 -> 817 | Q23: =IF(L23>0,MIN(L23,150),0) -> 150 | R23: =MAX(0,P23-Q23) -> 667 | T23: TBD
B24: Isabella Jones | C24: Houston, TX | D24: UT San Antonio | E24: San Antonio, TX | F24: 211 | H24: IAH | I24: SAT | J24: Short-haul flight | K24: 135 | L24: 66 | M24: 270 | N24: 50 | O24: 200 | P24: =K24+L24+M24+N24+O24 -> 721 | Q24: =IF(L24>0,MIN(L24,150),0) -> 66 | R24: =MAX(0,P24-Q24) -> 655 | T24: TBD
B25: Jimena | C25: St. Helena, CA | D25: University of Chicago | E25: Chicago, IL | F25: 2137 | H25: SFO | I25: ORD | J25: Cross-country flight | K25: 200 | L25: 168 | M25: 400 | N25: 50 | O25: 400 | P25: =K25+L25+M25+N25+O25 -> 1218 | Q25: =IF(L25>0,MIN(L25,150),0) -> 150 | R25: =MAX(0,P25-Q25) -> 1068 | T25: TBD
B26: Jocelyn Rico | C26: Vallejo, CA | D26: CSU Chico | E26: Chico, CA | F26: 134 | H26: N/A | I26: N/A | J26: Lyft | K26: 221 | L26: 0 | M26: 0 | N26: 0 | O26: 0 | P26: =K26+L26+M26+N26+O26 -> 221 | Q26: =IF(K26>0,MIN(K26,150),0) -> 150 | R26: =MAX(0,P26-Q26) -> 71 | T26: TBD
B27: Journey June Penterman | C27: Napa, CA | D27: Cal Poly SLO | E27: San Luis Obispo, CA | F27: 269 | H27: SFO | I27: SBP | J27: Short-haul flight | K27: 135 | L27: 116 | M27: 270 | N27: 50 | O27: 200 | P27: =K27+L27+M27+N27+O27 -> 771 | Q27: =IF(L27>0,MIN(L27,150),0) -> 116 | R27: =MAX(0,P27-Q27) -> 655 | T27: TBD
B28: Licendi Clavel Lopez | C28: Clearlake, CA | D28: UC Merced | E28: Merced, CA | F28: 220 | H28: N/A | I28: N/A | J28: Lyft | K28: 363 | L28: 0 | M28: 363 | N28: 0 | O28: 0 | P28: =K28+L28+M28+N28+O28 -> 726 | Q28: =IF(K28>0,MIN(K28,150),0) -> 150 | R28: =MAX(0,P28-Q28) -> 576 | T28: TBD
B29: Lilian Barrientos Aceituno | C29: American Canyon, CA | D29: The University of Chicago | E29: Chicago, IL | F29: 2108 | H29: SFO | I29: ORD | J29: Cross-country flight | K29: 200 | L29: 89 | M29: 0 | N29: 0 | O29: 0 | P29: =K29+L29+M29+N29+O29 -> 289 | Q29: =IF(L29>0,MIN(L29,150),0) -> 89 | R29: =MAX(0,P29-Q29) -> 200 | T29: TBD
B30: Lizbeth Perez Solano | C30: Napa, CA | D30: Napa Valley College | E30: Napa, CA | F30: <1 | H30: N/A | I30: N/A | J30: On campus | K30: 0 | L30: 0 | M30: 0 | N30: 0 | O30: 0 | P30: =K30+L30+M30+N30+O30 -> 0 | Q30: =IF(K30>0,MIN(K30,150),0) -> 0 | R30: =MAX(0,P30-Q30) -> 0 | T30: N/A
B31: Luna Esmeralda Juarez Alvarez | C31: Rohnert Park, CA | D31: SF State University | E31: San Francisco, CA | F31: 52 | H31: N/A | I31: N/A | J31: Lyft | K31: 86 | L31: 0 | M31: 0 | N31: 0 | O31: 0 | P31: =K31+L31+M31+N31+O31 -> 86 | Q31: =IF(K31>0,MIN(K31,150),0) -> 86 | R31: =MAX(0,P31-Q31) -> 0 | T31: TBD
B32: Marely Vazquez Garcia | C32: Petaluma, CA | D32: CSU Monterey Bay | E32: Seaside, CA | F32: 155 | H32: N/A | I32: N/A | J32: Lyft | K32: 256 | L32: 0 | M32: 256 | N32: 0 | O32: 0 | P32: =K32+L32+M32+N32+O32 -> 512 | Q32: =IF(K32>0,MIN(K32,150),0) -> 150 | R32: =MAX(0,P32-Q32) -> 362 | T32: TBD
B33: Maria Mosconi | C33: Napa, CA | D33: UC Berkeley | E33: Berkeley, CA | F33: 44 | H33: N/A | I33: N/A | J33: Lyft | K33: 73 | L33: 0 | M33: 0 | N33: 0 | O33: 0 | P33: =K33+L33+M33+N33+O33 -> 73 | Q33: =IF(K33>0,MIN(K33,150),0) -> 73 | R33: =MAX(0,P33-Q33) -> 0 | T33: TBD
B34: Marisol Navarro | C34: Saint Helena, CA | D34: CSU Chico | E34: Chico, CA | F34: 144 | H34: N/A | I34: N/A | J34: Lyft | K34: 238 | L34: 0 | M34: 0 | N34: 0 | O34: 0 | P34: =K34+L34+M34+N34+O34 -> 238 | Q34: =IF(K34>0,MIN(K34,150),0) -> 150 | R34: =MAX(0,P34-Q34) -> 88 | T34: TBD
B35: Melanie Avila | C35: Sonoma, CA | D35: Cal Poly SLO | E35: San Luis Obispo, CA | F35: 272 | H35: SFO | I35: SBP | J35: Short-haul flight | K35: 135 | L35: 124 | M35: 270 | N35: 50 | O35: 200 | P35: =K35+L35+M35+N35+O35 -> 779 | Q35: =IF(L35>0,MIN(L35,150),0) -> 124 | R35: =MAX(0,P35-Q35) -> 655 | T35: TBD
B36: Michelle Villafana | C36: American Canyon, CA | D36: UC San Diego | E36: San Diego, CA | F36: 505 | H36: SFO | I36: SAN | J36: Flight | K36: 135 | L36: 83 | M36: 0 | N36: 0 | O36: 0 | P36: =K36+L36+M36+N36+O36 -> 218 | Q36: =IF(L36>0,MIN(L36,150),0) -> 83 | R36: =MAX(0,P36-Q36) -> 135 | T36: TBD
B37: Nicholas Avery Joy | C37: Napa, CA | D37: Boston University | E37: Boston, MA | F37: 3071 | H37: SFO | I37: BOS | J37: Cross-country flight | K37: 220 | L37: 94 | M37: 0 | N37: 0 | O37: 0 | P37: =K37+L37+M37+N37+O37 -> 314 | Q37: =IF(L37>0,MIN(L37,150),0) -> 94 | R37: =MAX(0,P37-Q37) -> 220 | T37: No — BU
B38: Olivia Parriott | C38: Napa, CA | D38: UC Davis | E38: Davis, CA | F38: 52 | H38: N/A | I38: N/A | J38: Lyft | K38: 86 | L38: 0 | M38: 86 | N38: 0 | O38: 0 | P38: =K38+L38+M38+N38+O38 -> 172 | Q38: =IF(K38>0,MIN(K38,150),0) -> 86 | R38: =MAX(0,P38-Q38) -> 86 | T38: TBD
B39: Osvaldo Jr. Ramirez Hernandez | C39: Pope Valley, CA | D39: CSU San Marcos | E39: San Marcos, CA | F39: 536 | H39: SFO | I39: SAN | J39: Flight | K39: 135 | L39: 143 | M39: 0 | N39: 0 | O39: 0 | P39: =K39+L39+M39+N39+O39 -> 278 | Q39: =IF(L39>0,MIN(L39,150),0) -> 143 | R39: =MAX(0,P39-Q39) -> 135 | T39: TBD
B40: Reese Oo | C40: Rohnert Park, CA | D40: UCLA | E40: Westwood, CA | F40: 419 | H40: OAK | I40: LAX | J40: Short-haul flight | K40: 135 | L40: 137 | M40: 270 | N40: 50 | O40: 200 | P40: =K40+L40+M40+N40+O40 -> 792 | Q40: =IF(L40>0,MIN(L40,150),0) -> 137 | R40: =MAX(0,P40-Q40) -> 655 | T40: TBD
B41: Sara Ann Roberts | C41: Vallejo, CA | D41: UC Davis | E41: Davis, CA | F41: 42 | H41: N/A | I41: N/A | J41: Lyft | K41: 69 | L41: 0 | M41: 69 | N41: 0 | O41: 0 | P41: =K41+L41+M41+N41+O41 -> 138 | Q41: =IF(K41>0,MIN(K41,150),0) -> 69 | R41: =MAX(0,P41-Q41) -> 69 | T41: TBD
B42: Sofia Alvarez | C42: Napa, CA | D42: Univ of San Francisco | E42: San Francisco, CA | F42: 53 | H42: N/A | I42: N/A | J42: Lyft | K42: 87 | L42: 0 | M42: 0 | N42: 0 | O42: 0 | P42: =K42+L42+M42+N42+O42 -> 87 | Q42: =IF(K42>0,MIN(K42,150),0) -> 87 | R42: =MAX(0,P42-Q42) -> 0 | T42: TBD
...

Sheet Program Cost Pro Forma
B2: Campus Ready Foundation — 2026 Program Cost Pro Forma
B3: 40 eligible students. | Amber column = CollegeBoxes — PENDING BOARD APPROVAL. | CollegeBoxes policy (new): CRF pays only for schools that do not allow advance shipping. BU confirmed ineligible for advance shipping. All others TBD — research pending. | Col M = CRF cash outlay excluding CollegeBoxes. | Partner credits reduce cash outlay but not true cost to serve.
D5: TRUE COST TO SERVE | I5: PENDING | K5: PARTNER CREDITS
B6: Student Name | C6: Transport Mode | D6: Travel Cost | E6: Products $750 | F6: DoorDash $100 | G6: Gift Card $100 | H6: Total Cost to Serve | I6: CollegeBoxes (PENDING) | J6: Total incl. CollegeBoxes | K6: Lyft Credit | L6: DoorDash Credit | M6: CRF Cash Outlay | N6: Ships to Dorm?
B7: Nicholas Avery Joy | C7: Cross-country flight | D7: ='Travel Detail'!P7 -> 234 | E7: 750 | F7: 100 | G7: 100 | H7: =D7+E7+F7+G7 -> 1184 | I7: 250 | J7: =H7+I7 -> 1434 | K7: ='Travel Detail'!Q7 -> 150 | L7: 100 | M7: =MAX(0,H7-K7-L7) -> 934 | N7: No — BU
B8: Gabrielle Pina | C8: Cross-country flight | D8: ='Travel Detail'!P8 -> 828 | E8: 750 | F8: 100 | G8: 100 | H8: =D8+E8+F8+G8 -> 1778 | I8: 250 | J8: =H8+I8 -> 2028 | K8: ='Travel Detail'!Q8 -> 150 | L8: 100 | M8: =MAX(0,H8-K8-L8) -> 1528 | N8: TBD
B9: Elizabeth Carmichael | C9: Cross-country flight | D9: ='Travel Detail'!P9 -> 868 | E9: 750 | F9: 100 | G9: 100 | H9: =D9+E9+F9+G9 -> 1818 | I9: 250 | J9: =H9+I9 -> 2068 | K9: ='Travel Detail'!Q9 -> 0 | L9: 100 | M9: =MAX(0,H9-K9-L9) -> 1718 | N9: TBD
B10: Jimena | C10: Cross-country flight | D10: ='Travel Detail'!P10 -> 257 | E10: 750 | F10: 100 | G10: 100 | H10: =D10+E10+F10+G10 -> 1207 | I10: 250 | J10: =H10+I10 -> 1457 | K10: ='Travel Detail'!Q10 -> 150 | L10: 100 | M10: =MAX(0,H10-K10-L10) -> 957 | N10: TBD
B11: Lilian Barrientos Aceituno | C11: Cross-country flight | D11: ='Travel Detail'!P11 -> 129 | E11: 750 | F11: 100 | G11: 100 | H11: =D11+E11+F11+G11 -> 1079 | I11: 250 | J11: =H11+I11 -> 1329 | K11: ='Travel Detail'!Q11 -> 129 | L11: 100 | M11: =MAX(0,H11-K11-L11) -> 850 | N11: TBD
B12: Anastasia Guerrier | C12: Road trip (self-drive) | D12: ='Travel Detail'!P12 -> 218 | E12: 750 | F12: 100 | G12: 100 | H12: =D12+E12+F12+G12 -> 1168 | I12: 0 | J12: =H12+I12 -> 1168 | K12: ='Travel Detail'!Q12 -> 150 | L12: 100 | M12: =MAX(0,H12-K12-L12) -> 918 | N12: N/A
B13: Osvaldo Jr. Ramirez Hernandez | C13: Flight | D13: ='Travel Detail'!P13 -> 229 | E13: 750 | F13: 100 | G13: 100 | H13: =D13+E13+F13+G13 -> 1179 | I13: 150 | J13: =H13+I13 -> 1329 | K13: ='Travel Detail'!Q13 -> 94 | L13: 100 | M13: =MAX(0,H13-K13-L13) -> 985 | N13: TBD
B14: Amara S. Boerner | C14: Flight | D14: ='Travel Detail'!P14 -> 145 | E14: 750 | F14: 100 | G14: 100 | H14: =D14+E14+F14+G14 -> 1095 | I14: 150 | J14: =H14+I14 -> 1245 | K14: ='Travel Detail'!Q14 -> 145 | L14: 100 | M14: =MAX(0,H14-K14-L14) -> 850 | N14: TBD
B15: Arianna Deibert | C15: Flight | D15: ='Travel Detail'!P15 -> 548 | E15: 750 | F15: 100 | G15: 100 | H15: =D15+E15+F15+G15 -> 1498 | I15: 150 | J15: =H15+I15 -> 1648 | K15: ='Travel Detail'!Q15 -> 150 | L15: 100 | M15: =MAX(0,H15-K15-L15) -> 1248 | N15: TBD
B16: Michelle Villafana | C16: Flight | D16: ='Travel Detail'!P16 -> 438 | E16: 750 | F16: 100 | G16: 100 | H16: =D16+E16+F16+G16 -> 1388 | I16: 150 | J16: =H16+I16 -> 1538 | K16: ='Travel Detail'!Q16 -> 150 | L16: 100 | M16: =MAX(0,H16-K16-L16) -> 1138 | N16: TBD
B17: Henry Ray | C17: Short-haul flight | D17: ='Travel Detail'!P17 -> 25 | E17: 750 | F17: 100 | G17: 100 | H17: =D17+E17+F17+G17 -> 975 | I17: 150 | J17: =H17+I17 -> 1125 | K17: ='Travel Detail'!Q17 -> 25 | L17: 100 | M17: =MAX(0,H17-K17-L17) -> 850 | N17: TBD
B18: Reese Oo | C18: Short-haul flight | D18: ='Travel Detail'!P18 -> 472 | E18: 750 | F18: 100 | G18: 100 | H18: =D18+E18+F18+G18 -> 1422 | I18: 150 | J18: =H18+I18 -> 1572 | K18: ='Travel Detail'!Q18 -> 150 | L18: 100 | M18: =MAX(0,H18-K18-L18) -> 1172 | N18: TBD
... B47: Yadira Lizbeth Pelayo Avina | C47: Lyft | D47: ='Travel Detail'!P47 -> 80 | E47: 750 | F47: 100 | G47: 100 | H47: =D47+E47+F47+G47 -> 1030 | I47: 75 | J47: =H47+I47 -> 1105 | K47: ='Travel Detail'!Q47 -> 80 | L47: 100 | M47: =MAX(0,H47-K47-L47) -> 850 | N47: TBD
B48: TOTAL (41 students) | D48: =SUM(D7:D47) -> 15545 | E48: =SUM(E7:E47) -> 30750 | F48: =SUM(F7:F47) -> 4100 | G48: =SUM(G7:G47) -> 4100 | H48: =SUM(H7:H47) -> 54495 | I48: =SUM(I7:I47) -> 4475 | J48: =SUM(J7:J47) -> 58970 | K48: =SUM(K7:K47) -> 4609 | ... M48: =SUM(M7:M47) -> 45786
B50: NOTE: CRF Cash Outlay (col M) excludes CollegeBoxes. Add col I + col M for total cash outlay including CollegeBoxes. | DoorDash credit ($100) applies to all students. | CollegeBoxes eligibility contingent on school advance-shipping policy (col N). | See Travel Detail for per-student transport breakdown. See Appendix for all assumptions.

Sheet Appendix — Assumptions
B2: Campus Ready Foundation — Cost Model Assumptions & Methodology
B3: Documents every assumption, rate, and calculation underlying the travel and program cost models. Last updated May 2026.
B6: 1. Student Eligibility
B7: Eligible cohort | C7: 41 students. Ben Brakesman excluded — not confirmed living in on-campus housing (program eligibility requirement). Yadira Lizbeth Pelayo Avina re-included — on-campus housing at UC Davis confirmed via text May 2026.
B8: Lizbeth Perez Solano | C8: Included pending dorm confirmation at Napa Valley College. $0 travel cost. Will be removed if not living on campus.
B10: 2. Lyft Rate Assumptions
B11: Standard sedan — $1.10/mile | C11: Applied to airport legs for flight students: home→departure airport and arrival airport→campus. Students on these legs have minimal luggage (boxes shipped via CollegeBoxes ahead of time). $25 minimum per leg.
B12: Lyft XL — $1.65/mile | C12: Applied to all Lyft-direct-to-campus students. Student brings all belongings — SUV or minivan required. Also applied to home→airport leg when companion rides with student.
B13: $25 minimum per Lyft leg | C13: Accounts for base fare, booking fee, airport surcharges, and gratuity. Nicholas Avery Joy's BOS→Boston University leg (7mi) is a real-world example requiring the minimum.
B14: Rate source | C14: RideWise 2026 Rideshare Pricing Report (March 2026) and Lyft fare estimator. Lyft XL is 1.45–1.68x standard per current data. Rates are estimates — verify with Celia Moreno (Lyft partner) before finalizing.
B15: Pre-scheduling | C15: All rides will be pre-scheduled via CRF's Lyft partner relationship. Confirmation from Celia Moreno needed before June 1. UPDATED POLICY: Lyft threshold is 200 miles (reduced from 250 miles). Students 200–250 miles are assigned to short-haul flight where viable airport service exists.
B17: 3. Flight Students — Airport Lyft Legs
B18: Calculation method | C18: Straight-line haversine distance × 1.35 road factor for each leg. Road factor accounts for NorCal terrain and highway routing.
B19: Home → departure airport | C19: Standard sedan if student travels solo; Lyft XL if companion accompanies to airport (two passengers). $25 minimum.
B20: Arrival airport → campus | C20: Standard sedan for all students. Boxes shipped ahead via CollegeBoxes — only carry-on luggage at destination. $25 minimum.
B21: Departure airports | C21: SFO: most NorCal students (Napa, St. Helena, Angwin, Pope Valley, American Canyon, Santa Rosa, Petaluma, Rohnert Park). OAK: Reese Oo (Rohnert Park). BOS: Gabrielle Pina (Brockton, MA). IAH: Isabella Jones (Houston). N/A: Anastasia Guerrier (driving). SFO: Melanie Avila and Journey Penterman (now flying SFO→SBP — prev. Lyft overrides).
B23: 4. Flight Pricing (August 2026)
B24: Research source | C24: Kayak, Southwest, Skyscanner, Momondo, Expedia. Researched May 2026 for August 2026 travel window.
B25: Cross-country (1,000+ mi) | C25: $200 student one-way. $400 companion round-trip. SFO→ORD from $102 (Frontier August). SFO→CMH ~$175 (Southwest). MIA→MSP from $160 (Southwest August).
B26: Domestic flight (500–999 mi) | C26: $135 student one-way. Companion round-trip $270. August is lower-demand month for CA intra-state routes.
B27: Short-haul flight (200–499 mi) | C27: $135 student one-way. Companion round-trip $270. Threshold lowered from 250 to 200 miles for 2026 cycle. Melanie Avila and Journey Penterman (Cal Poly SLO) now fly SFO→SBP instead of Lyft. Isabella Jones (Houston→UTSA) now flies IAH→SAT.
B28: Booking urgency | C28: Book 4–6 weeks ahead. Momondo data shows August ORD average $336 for later bookings vs $102–133 when booked in advance.
B30: 5. Hotel Assumptions
B31: Rate | C31: $200 per night, all-in including taxes and fees.
B32: Eligibility | C32: UPDATED POLICY (2026): Hotel only for students traveling with a companion/guardian. Solo students proceed directly to the dorm on arrival — no hotel. Cross-country with companion: 2 nights ($400). Short-haul/domestic with companion: 1 night ($200). Road trip with companion (Anastasia Guerrier): 2 nights ($400) — 1 en route, 1 arrival night.
B34: 6. Companion Coverage
B35: Lyft credit scope | C35: $150 per student — applies to student's Lyft costs only. Cannot be applied to companion transport by default.
B36: Companion ground allowance | C36: $50 cash allowance for flight students whose companion travels with them. Covers companion's return Lyft from campus to nearest airport after move-in.
B37: Credit reallocation (planned) | C37: Eric to request Lyft partner approval to redirect unused student Lyft credits to companion ground transport. Many students have transport costs well under $150, leaving credits available. Expected approval — reduces actual cash outlay below model figures.
B38: Companion flights | C38: Companion round-trip airfare included for all flight students with companions. Same route and booking window as student. Road trip exception — Anastasia Guerrier: companion (mom) receives one-way return flight MSP→MIA (~$200) after driving student to campus. No round-trip needed.
B39: Road trip — Anastasia Guerrier | C39: Driving Miami, FL → St. Joseph, MN (1,861 mi). Gas card: $268 (1,861mi ÷ 28mpg × $3.50/gal × 1.15 contingency) — blue/editable in Travel Detail H12. Update when current gas prices confirmed. Companion return: one-way MSP→MIA ~$200. CollegeBoxes: $0 (driving all belongings). Hotel: 2 nights ($400).
B40: 7. CollegeBoxes Shipping — PENDING BOARD APPROVAL
B41: Status | C41: NOT APPROVED. Included for planning purposes only, shown in amber. NEW POLICY: CRF covers CollegeBoxes ONLY for schools that do not allow advance Amazon shipping to the dorm. For eligible schools: CRF directs Amazon product orders directly to the dorm — no separate shipping fee. If student at a ship-eligible school prefers home delivery, student bears own forward-shipping cost.
B42: Pricing basis | C42: CollegeBoxes (powered by U-Haul). Per box: in-state $45–60, regional $60–90, coast-to-coast $75–100, plus $30 handling fee per box (Ship to School). Source: collegeboxes.com/pricing, May 2026.
B43: Per-student allocations | C43: Cross-country flight (1,000+ mi): $250 — covers 2 boxes coast-to-coast. Domestic/short-haul flight: $150 — covers 1–2 boxes. Lyft-direct: $75 minimum allowance (Lyft XL carries most items, but allows for shipping fragile/bulky items).
B44: Total pending | C44: $4,175 across 40 students (reduced from $4,425 — Anastasia excluded, driving). BU (Boston University) confirmed no advance shipping: Nicholas Avery Joy eligible, $250. All other allocations contingent on school policy research (TBD). Amounts held at current levels pending school research.
B45: Rationale | C45: Flight students cannot bring all belongings in airline luggage (2 checked bags max). CollegeBoxes ships dorm supplies ahead of move-in day — student arrives, boxes are waiting. Lyft-direct students have more flexibility but may have fragile or oversized items.
B47: 8. Program Cost Assumptions
B48: Products | C48: $750 per student average. Covers school-specific move-in essentials selected from college checklist. Exact amount varies by school. Budget under refinement — may be adjusted before finalization.
B49: DoorDash Community Credits | C49: $100 per student digital credit code. Redeemable across full DoorDash platform. No expiration. Covers early-arrival meals before dining halls open. Source: DoorDash partner agreement (Victor Ruiz-Cornejo).
...
