Workbook

Sheet 2026 Operating Budget
A1: Campus Ready Foundation
A2: 2026 Operating Budget • For Board Approval • March 17, 2026
A4: KEY ASSUMPTIONS
A5: Students served (Cohort 1) | B5: 50 | E5: Summer 2026 — target cohort
A6: Average grant per student | B6: 2500 | E6: Essentials, travel, meals, incidentals
A7: Total program funding required | B7: =B5*B6 -> 125000
A9: AVAILABLE RESOURCES
A10: Source | B10: Amount | E10: Notes
A11: Cash on hand (Schwab, as of Mar 16) | B11: 23873.3 | E11: Update from latest statement
A12: Securities — donated equities | B12: ='Securities Detail'!E11 -> 17400.96 | E12: Current market value — see Securities Detail tab
A13: 2026 fundraising goal | B13: 100000 | E13: Donations, sponsors, partners, grants
A14: TOTAL AVAILABLE RESOURCES | B14: =SUM(B11:B13) -> 141274.26
A16: PROGRAM EXPENSES — Direct Student Support
A17: Category | B17: Per Student | C17: Total | E17: Notes
A18: Move-in essentials kit | B18: 750 | C18: =B18*$B$5 -> 37500 | E18: Bedding, bath, storage, personal care
A19: Travel & transportation | B19: 1500 | C19: =B19*$B$5 -> 75000 | E19: Flights, ground transport, hotel
A20: Early-arrival meals | B20: 150 | C20: =B20*$B$5 -> 7500 | E20: Campus meals before meal plan starts
A21: Incidentals gift card | B21: 100 | C21: =B21*$B$5 -> 5000 | E21: Student discretionary spending
A22: Subtotal — Program | B22: =SUM(B18:B21) -> 2500 | C22: =SUM(C18:C21) -> 125000
A24: OPERATING EXPENSES
A25: Category | C25: Annual | E25: Notes
A26: Software subscriptions | C26: 282 | E26: Claude $20/mo + Google Workspace $3.50/mo
A27: Printing | C27: 100 | E27: Periodic — estimated
A28: Office supplies | C28: 100 | E28: Estimated
A29: Equipment — iPad | C29: 1200 | E29: One-time purchase
A30: State filing fees | C30: 25 | E30: CA AG annual renewal (RRF-1)
A31: Subtotal — Operating | C31: =SUM(C26:C30) -> 1707
A33: BUDGET SUMMARY
A34: Total program expenses | C34: =C22 -> 125000
A35: Total operating expenses | C35: =C31 -> 1707
A36: TOTAL EXPENSES | C36: =C34+C35 -> 126707
A37: Total available resources | C37: =B14 -> 141274.26
A38: SURPLUS / (DEFICIT) | C38: =C37-C36 -> 14567.26
A40: Program expense ratio | C40: =IF(C36>0,C34/C36,0) -> 0.98652797 | E40: % of spending on direct student support
A41: Cost per student (all-in) | C41: =IF(B5>0,C36/B5,0) -> 2534.14 | E41: Total expenses ÷ students served
A43: FUNDING GAP — For Donor & Partner Conversations
A44: Total expenses to serve 50 students | C44: =C36 -> 126707
A45: Less: Cash and securities on hand | C45: =B11+B12 -> 41274.26
A46: REMAINING GAP TO CLOSE | C46: =C44-C45 -> 85432.74
A47: Every $2,500 raised funds one student's complete move-in experience — essentials, travel, meals, and incidentals.
...

Sheet Financial Position
A1: Campus Ready Foundation
A2: Financial Position • As of May 11, 2026
A4: LIQUID ASSETS
A5: Cash (Schwab sweep + money market) | B5: 23873.3 | D5: ⚠ Update manually from Schwab statement
A6: Securities — donated equities | B6: ='Securities Detail'!E11 -> 17400.96 | D6: Pulls from Securities Detail tab
A7: Unrealized gain / (loss) on securities | B7: ='Securities Detail'!F11 -> 466.46 | D7: Informational only — not included in total
A8: TOTAL LIQUID ASSETS | B8: =SUM(B5:B6) -> 41274.26
A10: 2026 OPERATING EXPENSES (YTD)
A11: Total operating expenses paid | B11: ='Monthly Tracker'!O22-'Monthly Tracker'!O21 -> 1384.12 | D11: See Monthly Tracker for line-item detail
A13: NET POSITION
A14: Total liquid assets | B14: =B8 -> 41274.26
A15: Less: YTD operating expenses | B15: =B11 -> 1384.12
A16: CURRENT NET POSITION | B16: =B14-B15 -> 39890.14
A18: FUNDRAISING PROGRESS
A19: Cash donations received (YTD) | B19: ='Monthly Tracker'!O6+'Monthly Tracker'!O7 -> 8350 | D19: Givebutter + Direct donations from Monthly Tracker
A20: Investment income (YTD) | B20: ='Monthly Tracker'!O8 -> 120.98
A21: 2026 fundraising goal | B21: 100000
A22: Fundraising progress (cash donations ÷ goal) | B22: =B19/B21 -> 0.0835
A24: IN-KIND PARTNER COMMITMENTS | D24: These are student-redeemable credits — not liquid assets
A25: Lyft — Ride Credits | B25: 7500
A26: DoorDash — Community Credits | B26: 5000
A27: TOTAL IN-KIND COMMITTED | B27: ='Monthly Tracker'!O9 -> 12500 | D27: Cross-checks Monthly Tracker Sponsors/Partners row
A29: HOW TO UPDATE THIS SHEET
A30: 1. Change the date in row 2.
A31: 2. Update cash on hand (cell B5) from your current Schwab statement.
A32: 3. Update Disney stock current value in the Securities Detail tab.
A33: 4. Enter new expenses in the Monthly Tracker as they occur.
A34: 5. Enter new donations and in-kind commitments in the Monthly Tracker as they occur.
A35: 6. All other cells (expenses, fundraising progress, in-kind total, net position) recalculate automatically.

Sheet Monthly Tracker
A1: Campus Ready Foundation
A2: 2026 Monthly Budget vs. Actual • Enter actual amounts each month • Blue = input
A4: REVENUE
A5: Source | B5: Annual Budget | C5: Jan | D5: Feb | E5: Mar | F5: Apr | G5: May | H5: Jun | I5: Jul | J5: Aug | K5: Sep | L5: Oct | M5: Nov | N5: Dec | O5: YTD Actual | P5: Remaining
A6: Donations — Givebutter | B6: 0 | C6: 0 | D6: 0 | E6: 2600 | F6: 0 | G6: 0 | H6: 0 | I6: 0 | J6: 0 | K6: 0 | L6: 0 | M6: 0 | N6: 0 | O6: =SUM(C6:N6) -> 2600 | P6: =B6-O6 -> -2600
A7: Donations — Direct | B7: 0 | C7: 250 | D7: 500 | E7: 2500 | F7: 2500 | G7: 0 | H7: 0 | I7: 0 | J7: 0 | K7: 0 | L7: 0 | M7: 0 | N7: 0 | O7: =SUM(C7:N7) -> 5750 | P7: =B7-O7 -> -5750
A8: Investment income | B8: 500 | C8: 120.98 | D8: 0 | E8: 0 | F8: 0 | G8: 0 | H8: 0 | I8: 0 | J8: 0 | K8: 0 | L8: 0 | M8: 0 | N8: 0 | O8: =SUM(C8:N8) -> 120.98 | P8: =B8-O8 -> 379.02
A9: Sponsors / Partners / Grants | B9: 0 | C9: 7500 | D9: 0 | E9: 5000 | F9: 0 | G9: 0 | H9: 0 | I9: 0 | J9: 0 | K9: 0 | L9: 0 | M9: 0 | N9: 0 | O9: =SUM(C9:N9) -> 12500 | P9: =B9-O9 -> -12500
A10: TOTAL REVENUE | B10: 100000 | C10: =SUM(C6:C9) -> 7870.98 | D10: =SUM(D6:D9) -> 500 | E10: =SUM(E6:E9) -> 10100 | F10: =SUM(F6:F9) -> 2500 | G10: =SUM(G6:G9) -> 0 | H10: =SUM(H6:H9) -> 0 | I10: =SUM(I6:I9) -> 0 | J10: =SUM(J6:J9) -> 0 | ... O10: =SUM(O6:O9) -> 20970.98 | P10: =B10-O10 -> 79029.02
A12: EXPENSES
A13: Category | B13: Annual Budget | C13: Jan | D13: Feb | E13: Mar | F13: Apr | G13: May | H13: Jun | I13: Jul | J13: Aug | K13: Sep | L13: Oct | M13: Nov | N13: Dec | O13: YTD Actual | P13: Remaining
A14: Software subscriptions | B14: 282 | C14: 103.5 | D14: 23.5 | E14: 23.5 | F14: 0 | G14: 0 | H14: 0 | I14: 0 | J14: 0 | K14: 0 | L14: 0 | M14: 0 | N14: 0 | O14: =SUM(C14:N14) -> 150.5 | P14: =B14-O14 -> 131.5
A15: Printing | B15: 100 | C15: 13.48 | D15: 0 | E15: 0 | F15: 0 | G15: 0 | H15: 0 | I15: 0 | J15: 0 | K15: 0 | L15: 0 | M15: 0 | N15: 0 | O15: =SUM(C15:N15) -> 13.48 | P15: =B15-O15 -> 86.52
A16: Office supplies | B16: 100 | C16: 21.37 | D16: 0 | E16: 0 | F16: 0 | G16: 0 | H16: 0 | I16: 0 | J16: 0 | K16: 0 | L16: 0 | M16: 0 | N16: 0 | O16: =SUM(C16:N16) -> 21.37 | P16: =B16-O16 -> 78.63
A17: Equipment — MacBook Air | B17: 0 | C17: 1123.79 | D17: 0 | E17: 0 | F17: 0 | G17: 0 | H17: 0 | I17: 0 | J17: 0 | K17: 0 | L17: 0 | M17: 0 | N17: 0 | O17: =SUM(C17:N17) -> 1123.79 | P17: =B17-O17 -> -1123.79
A18: Equipment — iPad | B18: 1200 | C18: 0 | D18: 0 | E18: 0 | F18: 0 | G18: 0 | H18: 0 | I18: 0 | J18: 0 | K18: 0 | L18: 0 | M18: 0 | N18: 0 | O18: =SUM(C18:N18) -> 0 | P18: =B18-O18 -> 1200
A19: Schwab advisor fee | B19: 0 | C19: 74.98 | D19: 0 | E19: 0 | F19: 0 | G19: 0 | H19: 0 | I19: 0 | J19: 0 | K19: 0 | L19: 0 | M19: 0 | N19: 0 | O19: =SUM(C19:N19) -> 74.98 | P19: =B19-O19 -> -74.98
A20: State filing fees | B20: 25 | C20: 0 | D20: 0 | E20: 0 | F20: 0 | G20: 0 | H20: 0 | I20: 0 | J20: 0 | K20: 0 | L20: 0 | M20: 0 | N20: 0 | O20: =SUM(C20:N20) -> 0 | P20: =B20-O20 -> 25
A21: Program expenses — student grants | B21: 125000 | C21: 0 | D21: 0 | E21: 0 | F21: 0 | G21: 0 | H21: 0 | I21: 0 | J21: 0 | K21: 0 | L21: 0 | M21: 0 | N21: 0 | O21: =SUM(C21:N21) -> 0 | P21: =B21-O21 -> 125000
A22: TOTAL EXPENSES | B22: =SUM(B14:B21) -> 126707 | C22: =SUM(C14:C21) -> 1337.12 | D22: =SUM(D14:D21) -> 23.5 | E22: =SUM(E14:E21) -> 23.5 | F22: =SUM(F14:F21) -> 0 | G22: =SUM(G14:G21) -> 0 | H22: =SUM(H14:H21) -> 0 | I22: =SUM(I14:I21) -> 0 | ... O22: =SUM(O14:O21) -> 1384.12 | P22: =B22-O22 -> 125322.88
A24: MONTHLY NET (Revenue − Expenses)
A25: Net monthly activity | B25: =B10-B22 -> -26707 | C25: =C10-C22 -> 6533.86 | D25: =D10-D22 -> 476.5 | E25: =E10-E22 -> 10076.5 | F25: =F10-F22 -> 2500 | G25: =G10-G22 -> 0 | H25: =H10-H22 -> 0 | I25: =I10-I22 -> 0 | ... O25: =O10-O22 -> 19586.86
A27: Enter actual amounts in the month columns as transactions occur. YTD and Remaining columns calculate automatically. MacBook and Schwab fee are unbudgeted actuals — they show a negative Remaining, which is expected.

Sheet Securities Detail
A1: Campus Ready Foundation
A2: Securities Detail • Update current values when refreshing Financial Position
A4: DONATED SECURITIES
A5: Donation | B5: Date Received | C5: Original FMV | D5: Sold to Cash | E5: Current Value | F5: Gain / (Loss) | G5: Notes
A6: DIS + JPM (Eric & Karen Lilavois) | B6: Nov 17, 2025 | C6: 20135.01 | D6: 3200.51 | E6: 17400.96 | F6: =E6-(C6-D6) -> 466.46 | G6: JPM sold Dec 2025. 161.09 DIS shares remain.
F7: =IF(C7>0,E7-(C7-D7),0) -> 0
F8: =IF(C8>0,E8-(C8-D8),0) -> 0
F9: =IF(C9>0,E9-(C9-D9),0) -> 0
F10: =IF(C10>0,E10-(C10-D10),0) -> 0
A11: TOTAL SECURITIES | C11: =SUM(C6:C10) -> 20135.01 | D11: =SUM(D6:D10) -> 3200.51 | E11: =SUM(E6:E10) -> 17400.96 | F11: =SUM(F6:F10) -> 466.46
A13: How to add a new donation
A14: 1. Insert a row above the TOTAL SECURITIES row (row 11).
A15: 2. Enter the donation name, date, original FMV, and any shares sold.
A16: 3. Enter current market value — update this each time you refresh.
A17: 4. Gain / (Loss) calculates automatically. Totals update automatically.
A18: 5. Financial Position and Operating Budget pull from the Total Securities row — no other changes needed.
